joshuamontoya@MacBookPro ~/np-analytics-app                                                                     [13:11:56] 
> $ python3 run_jobs.py                                                                                          [¬±main ‚úì]
2025-08-22 13:16:35,457 | INFO     | üåê Warm-up ping returned 200
2025-08-22 13:16:35,458 | INFO     | üóìÔ∏è Last Sunday (CST): 2025-08-17
2025-08-22 13:16:35,458 | INFO     | üì° Calling: http://127.0.0.1:8000/planning-center/people/sync ‚Äì People sync
2025-08-22 13:21:35,461 | ERROR    | ‚ùå Error calling People sync: HTTPConnectionPool(host='127.0.0.1', port=8000): Read timed out. (read timeout=300)
Traceback (most recent call last):
  File "/Library/Frameworks/Python.framework/Versions/3.10/lib/python3.10/site-packages/urllib3/connectionpool.py", line 449, in _make_request
    six.raise_from(e, None)
  File "<string>", line 3, in raise_from
  File "/Library/Frameworks/Python.framework/Versions/3.10/lib/python3.10/site-packages/urllib3/connectionpool.py", line 444, in _make_request
    httplib_response = conn.getresponse()
  File "/Library/Frameworks/Python.framework/Versions/3.10/lib/python3.10/http/client.py", line 1374, in getresponse
    response.begin()
  File "/Library/Frameworks/Python.framework/Versions/3.10/lib/python3.10/http/client.py", line 318, in begin
    version, status, reason = self._read_status()
  File "/Library/Frameworks/Python.framework/Versions/3.10/lib/python3.10/http/client.py", line 279, in _read_status
    line = str(self.fp.readline(_MAXLINE + 1), "iso-8859-1")
  File "/Library/Frameworks/Python.framework/Versions/3.10/lib/python3.10/socket.py", line 705, in readinto
    return self._sock.recv_into(b)
TimeoutError: timed out

During handling of the above exception, another exception occurred:

Traceback (most recent call last):
  File "/Library/Frameworks/Python.framework/Versions/3.10/lib/python3.10/site-packages/requests/adapters.py", line 489, in send
    resp = conn.urlopen(
  File "/Library/Frameworks/Python.framework/Versions/3.10/lib/python3.10/site-packages/urllib3/connectionpool.py", line 787, in urlopen
    retries = retries.increment(
  File "/Library/Frameworks/Python.framework/Versions/3.10/lib/python3.10/site-packages/urllib3/util/retry.py", line 550, in increment
    raise six.reraise(type(error), error, _stacktrace)
  File "/Library/Frameworks/Python.framework/Versions/3.10/lib/python3.10/site-packages/urllib3/packages/six.py", line 770, in reraise
    raise value
  File "/Library/Frameworks/Python.framework/Versions/3.10/lib/python3.10/site-packages/urllib3/connectionpool.py", line 703, in urlopen
    httplib_response = self._make_request(
  File "/Library/Frameworks/Python.framework/Versions/3.10/lib/python3.10/site-packages/urllib3/connectionpool.py", line 451, in _make_request
    self._raise_timeout(err=e, url=url, timeout_value=read_timeout)
  File "/Library/Frameworks/Python.framework/Versions/3.10/lib/python3.10/site-packages/urllib3/connectionpool.py", line 340, in _raise_timeout
    raise ReadTimeoutError(
urllib3.exceptions.ReadTimeoutError: HTTPConnectionPool(host='127.0.0.1', port=8000): Read timed out. (read timeout=300)

During handling of the above exception, another exception occurred:

Traceback (most recent call last):
  File "/Users/joshuamontoya/np-analytics-app/run_jobs.py", line 52, in call_job
    r = requests.get(url, timeout=timeout)
  File "/Library/Frameworks/Python.framework/Versions/3.10/lib/python3.10/site-packages/requests/api.py", line 73, in get
    return request("get", url, params=params, **kwargs)
  File "/Library/Frameworks/Python.framework/Versions/3.10/lib/python3.10/site-packages/requests/api.py", line 59, in request
    return session.request(method=method, url=url, **kwargs)
  File "/Library/Frameworks/Python.framework/Versions/3.10/lib/python3.10/site-packages/requests/sessions.py", line 587, in request
    resp = self.send(prep, **send_kwargs)
  File "/Library/Frameworks/Python.framework/Versions/3.10/lib/python3.10/site-packages/requests/sessions.py", line 701, in send
    r = adapter.send(request, **kwargs)
  File "/Library/Frameworks/Python.framework/Versions/3.10/lib/python3.10/site-packages/requests/adapters.py", line 578, in send
    raise ReadTimeout(e, request=request)
requests.exceptions.ReadTimeout: HTTPConnectionPool(host='127.0.0.1', port=8000): Read timed out. (read timeout=300)
2025-08-22 13:21:36,975 | INFO     | üì° Calling: http://127.0.0.1:8000/planning-center/groups/sync ‚Äì Groups/memberships sync
2025-08-22 13:26:36,985 | ERROR    | ‚ùå Error calling Groups/memberships sync: HTTPConnectionPool(host='127.0.0.1', port=8000): Read timed out. (read timeout=300)
Traceback (most recent call last):
  File "/Library/Frameworks/Python.framework/Versions/3.10/lib/python3.10/site-packages/urllib3/connectionpool.py", line 449, in _make_request
    six.raise_from(e, None)
  File "<string>", line 3, in raise_from
  File "/Library/Frameworks/Python.framework/Versions/3.10/lib/python3.10/site-packages/urllib3/connectionpool.py", line 444, in _make_request
    httplib_response = conn.getresponse()
  File "/Library/Frameworks/Python.framework/Versions/3.10/lib/python3.10/http/client.py", line 1374, in getresponse
    response.begin()
  File "/Library/Frameworks/Python.framework/Versions/3.10/lib/python3.10/http/client.py", line 318, in begin
    version, status, reason = self._read_status()
  File "/Library/Frameworks/Python.framework/Versions/3.10/lib/python3.10/http/client.py", line 279, in _read_status
    line = str(self.fp.readline(_MAXLINE + 1), "iso-8859-1")
  File "/Library/Frameworks/Python.framework/Versions/3.10/lib/python3.10/socket.py", line 705, in readinto
    return self._sock.recv_into(b)
TimeoutError: timed out

During handling of the above exception, another exception occurred:

Traceback (most recent call last):
  File "/Library/Frameworks/Python.framework/Versions/3.10/lib/python3.10/site-packages/requests/adapters.py", line 489, in send
    resp = conn.urlopen(
  File "/Library/Frameworks/Python.framework/Versions/3.10/lib/python3.10/site-packages/urllib3/connectionpool.py", line 787, in urlopen
    retries = retries.increment(
  File "/Library/Frameworks/Python.framework/Versions/3.10/lib/python3.10/site-packages/urllib3/util/retry.py", line 550, in increment
    raise six.reraise(type(error), error, _stacktrace)
  File "/Library/Frameworks/Python.framework/Versions/3.10/lib/python3.10/site-packages/urllib3/packages/six.py", line 770, in reraise
    raise value
  File "/Library/Frameworks/Python.framework/Versions/3.10/lib/python3.10/site-packages/urllib3/connectionpool.py", line 703, in urlopen
    httplib_response = self._make_request(
  File "/Library/Frameworks/Python.framework/Versions/3.10/lib/python3.10/site-packages/urllib3/connectionpool.py", line 451, in _make_request
    self._raise_timeout(err=e, url=url, timeout_value=read_timeout)
  File "/Library/Frameworks/Python.framework/Versions/3.10/lib/python3.10/site-packages/urllib3/connectionpool.py", line 340, in _raise_timeout
    raise ReadTimeoutError(
urllib3.exceptions.ReadTimeoutError: HTTPConnectionPool(host='127.0.0.1', port=8000): Read timed out. (read timeout=300)

During handling of the above exception, another exception occurred:

Traceback (most recent call last):
  File "/Users/joshuamontoya/np-analytics-app/run_jobs.py", line 52, in call_job
    r = requests.get(url, timeout=timeout)
  File "/Library/Frameworks/Python.framework/Versions/3.10/lib/python3.10/site-packages/requests/api.py", line 73, in get
    return request("get", url, params=params, **kwargs)
  File "/Library/Frameworks/Python.framework/Versions/3.10/lib/python3.10/site-packages/requests/api.py", line 59, in request
    return session.request(method=method, url=url, **kwargs)
  File "/Library/Frameworks/Python.framework/Versions/3.10/lib/python3.10/site-packages/requests/sessions.py", line 587, in request
    resp = self.send(prep, **send_kwargs)
  File "/Library/Frameworks/Python.framework/Versions/3.10/lib/python3.10/site-packages/requests/sessions.py", line 701, in send
    r = adapter.send(request, **kwargs)
  File "/Library/Frameworks/Python.framework/Versions/3.10/lib/python3.10/site-packages/requests/adapters.py", line 578, in send
    raise ReadTimeout(e, request=request)
requests.exceptions.ReadTimeout: HTTPConnectionPool(host='127.0.0.1', port=8000): Read timed out. (read timeout=300)
2025-08-22 13:26:38,497 | INFO     | üì° Calling: http://127.0.0.1:8000/planning-center/serving/sync ‚Äì Serving teams/memberships sync
2025-08-22 13:29:22,989 | INFO     | ‚úÖ Finished: Serving teams/memberships sync (200)
2025-08-22 13:29:24,500 | INFO     | üì° Calling: http://127.0.0.1:8000/planning-center/checkins?date=2025-08-17 ‚Äì Check-ins ingest (last Sunday)
2025-08-22 13:30:45,846 | INFO     | ‚úÖ Finished: Check-ins ingest (last Sunday) (200)
2025-08-22 13:30:47,354 | INFO     | üì° Calling: http://127.0.0.1:8000/planning-center/giving/weekly-summary ‚Äì Giving summary (last full week)
2025-08-22 13:31:00,814 | INFO     | ‚úÖ Finished: Giving summary (last full week) (200)
2025-08-22 13:31:02,324 | INFO     | üì° Calling: http://127.0.0.1:8000/analytics/cadence/rebuild?signals=attend,give,group,serve&since=2025-08-09&rolling_days=180&week_end=2025-08-17 ‚Äì Cadence rebuild
2025-08-22 13:33:40,611 | INFO     | ‚úÖ Finished: Cadence rebuild (200)
2025-08-22 13:33:42,121 | INFO     | üì° Calling: http://127.0.0.1:8000/analytics/cadence/snap-week?week_end=2025-08-17 ‚Äì Cadence snapshot
2025-08-22 13:38:42,154 | ERROR    | ‚ùå Error calling Cadence snapshot: HTTPConnectionPool(host='127.0.0.1', port=8000): Read timed out. (read timeout=300)
Traceback (most recent call last):
  File "/Library/Frameworks/Python.framework/Versions/3.10/lib/python3.10/site-packages/urllib3/connectionpool.py", line 449, in _make_request
    six.raise_from(e, None)
  File "<string>", line 3, in raise_from
  File "/Library/Frameworks/Python.framework/Versions/3.10/lib/python3.10/site-packages/urllib3/connectionpool.py", line 444, in _make_request
    httplib_response = conn.getresponse()
  File "/Library/Frameworks/Python.framework/Versions/3.10/lib/python3.10/http/client.py", line 1374, in getresponse
    response.begin()
  File "/Library/Frameworks/Python.framework/Versions/3.10/lib/python3.10/http/client.py", line 318, in begin
    version, status, reason = self._read_status()
  File "/Library/Frameworks/Python.framework/Versions/3.10/lib/python3.10/http/client.py", line 279, in _read_status
    line = str(self.fp.readline(_MAXLINE + 1), "iso-8859-1")
  File "/Library/Frameworks/Python.framework/Versions/3.10/lib/python3.10/socket.py", line 705, in readinto
    return self._sock.recv_into(b)
TimeoutError: timed out

During handling of the above exception, another exception occurred:

Traceback (most recent call last):
  File "/Library/Frameworks/Python.framework/Versions/3.10/lib/python3.10/site-packages/requests/adapters.py", line 489, in send
    resp = conn.urlopen(
  File "/Library/Frameworks/Python.framework/Versions/3.10/lib/python3.10/site-packages/urllib3/connectionpool.py", line 787, in urlopen
    retries = retries.increment(
  File "/Library/Frameworks/Python.framework/Versions/3.10/lib/python3.10/site-packages/urllib3/util/retry.py", line 550, in increment
    raise six.reraise(type(error), error, _stacktrace)
  File "/Library/Frameworks/Python.framework/Versions/3.10/lib/python3.10/site-packages/urllib3/packages/six.py", line 770, in reraise
    raise value
  File "/Library/Frameworks/Python.framework/Versions/3.10/lib/python3.10/site-packages/urllib3/connectionpool.py", line 703, in urlopen
    httplib_response = self._make_request(
  File "/Library/Frameworks/Python.framework/Versions/3.10/lib/python3.10/site-packages/urllib3/connectionpool.py", line 451, in _make_request
    self._raise_timeout(err=e, url=url, timeout_value=read_timeout)
  File "/Library/Frameworks/Python.framework/Versions/3.10/lib/python3.10/site-packages/urllib3/connectionpool.py", line 340, in _raise_timeout
    raise ReadTimeoutError(
urllib3.exceptions.ReadTimeoutError: HTTPConnectionPool(host='127.0.0.1', port=8000): Read timed out. (read timeout=300)

During handling of the above exception, another exception occurred:

Traceback (most recent call last):
  File "/Users/joshuamontoya/np-analytics-app/run_jobs.py", line 52, in call_job
    r = requests.get(url, timeout=timeout)
  File "/Library/Frameworks/Python.framework/Versions/3.10/lib/python3.10/site-packages/requests/api.py", line 73, in get
    return request("get", url, params=params, **kwargs)
  File "/Library/Frameworks/Python.framework/Versions/3.10/lib/python3.10/site-packages/requests/api.py", line 59, in request
    return session.request(method=method, url=url, **kwargs)
  File "/Library/Frameworks/Python.framework/Versions/3.10/lib/python3.10/site-packages/requests/sessions.py", line 587, in request
    resp = self.send(prep, **send_kwargs)
  File "/Library/Frameworks/Python.framework/Versions/3.10/lib/python3.10/site-packages/requests/sessions.py", line 701, in send
    r = adapter.send(request, **kwargs)
  File "/Library/Frameworks/Python.framework/Versions/3.10/lib/python3.10/site-packages/requests/adapters.py", line 578, in send
    raise ReadTimeout(e, request=request)
requests.exceptions.ReadTimeout: HTTPConnectionPool(host='127.0.0.1', port=8000): Read timed out. (read timeout=300)
2025-08-22 13:38:43,669 | INFO     | üì° Calling: http://127.0.0.1:8000/analytics/cadence/weekly-report?week_end=2025-08-17&ensure_snapshot=true&persist_front_door=true ‚Äì Cadence weekly-report
2025-08-22 13:43:43,682 | ERROR    | ‚ùå Error calling Cadence weekly-report: HTTPConnectionPool(host='127.0.0.1', port=8000): Read timed out. (read timeout=300)
Traceback (most recent call last):
  File "/Library/Frameworks/Python.framework/Versions/3.10/lib/python3.10/site-packages/urllib3/connectionpool.py", line 449, in _make_request
    six.raise_from(e, None)
  File "<string>", line 3, in raise_from
  File "/Library/Frameworks/Python.framework/Versions/3.10/lib/python3.10/site-packages/urllib3/connectionpool.py", line 444, in _make_request
    httplib_response = conn.getresponse()
  File "/Library/Frameworks/Python.framework/Versions/3.10/lib/python3.10/http/client.py", line 1374, in getresponse
    response.begin()
  File "/Library/Frameworks/Python.framework/Versions/3.10/lib/python3.10/http/client.py", line 318, in begin
    version, status, reason = self._read_status()
  File "/Library/Frameworks/Python.framework/Versions/3.10/lib/python3.10/http/client.py", line 279, in _read_status
    line = str(self.fp.readline(_MAXLINE + 1), "iso-8859-1")
  File "/Library/Frameworks/Python.framework/Versions/3.10/lib/python3.10/socket.py", line 705, in readinto
    return self._sock.recv_into(b)
TimeoutError: timed out

During handling of the above exception, another exception occurred:

Traceback (most recent call last):
  File "/Library/Frameworks/Python.framework/Versions/3.10/lib/python3.10/site-packages/requests/adapters.py", line 489, in send
    resp = conn.urlopen(
  File "/Library/Frameworks/Python.framework/Versions/3.10/lib/python3.10/site-packages/urllib3/connectionpool.py", line 787, in urlopen
    retries = retries.increment(
  File "/Library/Frameworks/Python.framework/Versions/3.10/lib/python3.10/site-packages/urllib3/util/retry.py", line 550, in increment
    raise six.reraise(type(error), error, _stacktrace)
  File "/Library/Frameworks/Python.framework/Versions/3.10/lib/python3.10/site-packages/urllib3/packages/six.py", line 770, in reraise
    raise value
  File "/Library/Frameworks/Python.framework/Versions/3.10/lib/python3.10/site-packages/urllib3/connectionpool.py", line 703, in urlopen
    httplib_response = self._make_request(
  File "/Library/Frameworks/Python.framework/Versions/3.10/lib/python3.10/site-packages/urllib3/connectionpool.py", line 451, in _make_request
    self._raise_timeout(err=e, url=url, timeout_value=read_timeout)
  File "/Library/Frameworks/Python.framework/Versions/3.10/lib/python3.10/site-packages/urllib3/connectionpool.py", line 340, in _raise_timeout
    raise ReadTimeoutError(
urllib3.exceptions.ReadTimeoutError: HTTPConnectionPool(host='127.0.0.1', port=8000): Read timed out. (read timeout=300)

During handling of the above exception, another exception occurred:

Traceback (most recent call last):
  File "/Users/joshuamontoya/np-analytics-app/run_jobs.py", line 52, in call_job
    r = requests.get(url, timeout=timeout)
  File "/Library/Frameworks/Python.framework/Versions/3.10/lib/python3.10/site-packages/requests/api.py", line 73, in get
    return request("get", url, params=params, **kwargs)
  File "/Library/Frameworks/Python.framework/Versions/3.10/lib/python3.10/site-packages/requests/api.py", line 59, in request
    return session.request(method=method, url=url, **kwargs)
  File "/Library/Frameworks/Python.framework/Versions/3.10/lib/python3.10/site-packages/requests/sessions.py", line 587, in request
    resp = self.send(prep, **send_kwargs)
  File "/Library/Frameworks/Python.framework/Versions/3.10/lib/python3.10/site-packages/requests/sessions.py", line 701, in send
    r = adapter.send(request, **kwargs)
  File "/Library/Frameworks/Python.framework/Versions/3.10/lib/python3.10/site-packages/requests/adapters.py", line 578, in send
    raise ReadTimeout(e, request=request)
requests.exceptions.ReadTimeout: HTTPConnectionPool(host='127.0.0.1', port=8000): Read timed out. (read timeout=300)
2025-08-22 13:43:43,684 | INFO     | ‚è≥ Cadence report not ready (attempt 1/8) ‚Äì waiting 10s
2025-08-22 13:43:53,692 | INFO     | üì° Calling: http://127.0.0.1:8000/analytics/cadence/weekly-report?week_end=2025-08-17&ensure_snapshot=true&persist_front_door=true ‚Äì Cadence weekly-report
2025-08-22 13:48:53,704 | ERROR    | ‚ùå Error calling Cadence weekly-report: HTTPConnectionPool(host='127.0.0.1', port=8000): Read timed out. (read timeout=300)
Traceback (most recent call last):
  File "/Library/Frameworks/Python.framework/Versions/3.10/lib/python3.10/site-packages/urllib3/connectionpool.py", line 449, in _make_request
    six.raise_from(e, None)
  File "<string>", line 3, in raise_from
  File "/Library/Frameworks/Python.framework/Versions/3.10/lib/python3.10/site-packages/urllib3/connectionpool.py", line 444, in _make_request
    httplib_response = conn.getresponse()
  File "/Library/Frameworks/Python.framework/Versions/3.10/lib/python3.10/http/client.py", line 1374, in getresponse
    response.begin()
  File "/Library/Frameworks/Python.framework/Versions/3.10/lib/python3.10/http/client.py", line 318, in begin
    version, status, reason = self._read_status()
  File "/Library/Frameworks/Python.framework/Versions/3.10/lib/python3.10/http/client.py", line 279, in _read_status
    line = str(self.fp.readline(_MAXLINE + 1), "iso-8859-1")
  File "/Library/Frameworks/Python.framework/Versions/3.10/lib/python3.10/socket.py", line 705, in readinto
    return self._sock.recv_into(b)
TimeoutError: timed out

During handling of the above exception, another exception occurred:

Traceback (most recent call last):
  File "/Library/Frameworks/Python.framework/Versions/3.10/lib/python3.10/site-packages/requests/adapters.py", line 489, in send
    resp = conn.urlopen(
  File "/Library/Frameworks/Python.framework/Versions/3.10/lib/python3.10/site-packages/urllib3/connectionpool.py", line 787, in urlopen
    retries = retries.increment(
  File "/Library/Frameworks/Python.framework/Versions/3.10/lib/python3.10/site-packages/urllib3/util/retry.py", line 550, in increment
    raise six.reraise(type(error), error, _stacktrace)
  File "/Library/Frameworks/Python.framework/Versions/3.10/lib/python3.10/site-packages/urllib3/packages/six.py", line 770, in reraise
    raise value
  File "/Library/Frameworks/Python.framework/Versions/3.10/lib/python3.10/site-packages/urllib3/connectionpool.py", line 703, in urlopen
    httplib_response = self._make_request(
  File "/Library/Frameworks/Python.framework/Versions/3.10/lib/python3.10/site-packages/urllib3/connectionpool.py", line 451, in _make_request
    self._raise_timeout(err=e, url=url, timeout_value=read_timeout)
  File "/Library/Frameworks/Python.framework/Versions/3.10/lib/python3.10/site-packages/urllib3/connectionpool.py", line 340, in _raise_timeout
    raise ReadTimeoutError(
urllib3.exceptions.ReadTimeoutError: HTTPConnectionPool(host='127.0.0.1', port=8000): Read timed out. (read timeout=300)

During handling of the above exception, another exception occurred:

Traceback (most recent call last):
  File "/Users/joshuamontoya/np-analytics-app/run_jobs.py", line 52, in call_job
    r = requests.get(url, timeout=timeout)
  File "/Library/Frameworks/Python.framework/Versions/3.10/lib/python3.10/site-packages/requests/api.py", line 73, in get
    return request("get", url, params=params, **kwargs)
  File "/Library/Frameworks/Python.framework/Versions/3.10/lib/python3.10/site-packages/requests/api.py", line 59, in request
    return session.request(method=method, url=url, **kwargs)
  File "/Library/Frameworks/Python.framework/Versions/3.10/lib/python3.10/site-packages/requests/sessions.py", line 587, in request
    resp = self.send(prep, **send_kwargs)
  File "/Library/Frameworks/Python.framework/Versions/3.10/lib/python3.10/site-packages/requests/sessions.py", line 701, in send
    r = adapter.send(request, **kwargs)
  File "/Library/Frameworks/Python.framework/Versions/3.10/lib/python3.10/site-packages/requests/adapters.py", line 578, in send
    raise ReadTimeout(e, request=request)
requests.exceptions.ReadTimeout: HTTPConnectionPool(host='127.0.0.1', port=8000): Read timed out. (read timeout=300)
2025-08-22 13:48:53,706 | INFO     | ‚è≥ Cadence report not ready (attempt 2/8) ‚Äì waiting 10s
2025-08-22 13:49:03,717 | INFO     | üì° Calling: http://127.0.0.1:8000/analytics/cadence/weekly-report?week_end=2025-08-17&ensure_snapshot=true&persist_front_door=true ‚Äì Cadence weekly-report
2025-08-22 13:54:03,712 | ERROR    | ‚ùå Error calling Cadence weekly-report: HTTPConnectionPool(host='127.0.0.1', port=8000): Read timed out. (read timeout=300)
Traceback (most recent call last):
  File "/Library/Frameworks/Python.framework/Versions/3.10/lib/python3.10/site-packages/urllib3/connectionpool.py", line 449, in _make_request
    six.raise_from(e, None)
  File "<string>", line 3, in raise_from
  File "/Library/Frameworks/Python.framework/Versions/3.10/lib/python3.10/site-packages/urllib3/connectionpool.py", line 444, in _make_request
    httplib_response = conn.getresponse()
  File "/Library/Frameworks/Python.framework/Versions/3.10/lib/python3.10/http/client.py", line 1374, in getresponse
    response.begin()
  File "/Library/Frameworks/Python.framework/Versions/3.10/lib/python3.10/http/client.py", line 318, in begin
    version, status, reason = self._read_status()
  File "/Library/Frameworks/Python.framework/Versions/3.10/lib/python3.10/http/client.py", line 279, in _read_status
    line = str(self.fp.readline(_MAXLINE + 1), "iso-8859-1")
  File "/Library/Frameworks/Python.framework/Versions/3.10/lib/python3.10/socket.py", line 705, in readinto
    return self._sock.recv_into(b)
TimeoutError: timed out

During handling of the above exception, another exception occurred:

Traceback (most recent call last):
  File "/Library/Frameworks/Python.framework/Versions/3.10/lib/python3.10/site-packages/requests/adapters.py", line 489, in send
    resp = conn.urlopen(
  File "/Library/Frameworks/Python.framework/Versions/3.10/lib/python3.10/site-packages/urllib3/connectionpool.py", line 787, in urlopen
    retries = retries.increment(
  File "/Library/Frameworks/Python.framework/Versions/3.10/lib/python3.10/site-packages/urllib3/util/retry.py", line 550, in increment
    raise six.reraise(type(error), error, _stacktrace)
  File "/Library/Frameworks/Python.framework/Versions/3.10/lib/python3.10/site-packages/urllib3/packages/six.py", line 770, in reraise
    raise value
  File "/Library/Frameworks/Python.framework/Versions/3.10/lib/python3.10/site-packages/urllib3/connectionpool.py", line 703, in urlopen
    httplib_response = self._make_request(
  File "/Library/Frameworks/Python.framework/Versions/3.10/lib/python3.10/site-packages/urllib3/connectionpool.py", line 451, in _make_request
    self._raise_timeout(err=e, url=url, timeout_value=read_timeout)
  File "/Library/Frameworks/Python.framework/Versions/3.10/lib/python3.10/site-packages/urllib3/connectionpool.py", line 340, in _raise_timeout
    raise ReadTimeoutError(
urllib3.exceptions.ReadTimeoutError: HTTPConnectionPool(host='127.0.0.1', port=8000): Read timed out. (read timeout=300)

During handling of the above exception, another exception occurred:

Traceback (most recent call last):
  File "/Users/joshuamontoya/np-analytics-app/run_jobs.py", line 52, in call_job
    r = requests.get(url, timeout=timeout)
  File "/Library/Frameworks/Python.framework/Versions/3.10/lib/python3.10/site-packages/requests/api.py", line 73, in get
    return request("get", url, params=params, **kwargs)
  File "/Library/Frameworks/Python.framework/Versions/3.10/lib/python3.10/site-packages/requests/api.py", line 59, in request
    return session.request(method=method, url=url, **kwargs)
  File "/Library/Frameworks/Python.framework/Versions/3.10/lib/python3.10/site-packages/requests/sessions.py", line 587, in request
    resp = self.send(prep, **send_kwargs)
  File "/Library/Frameworks/Python.framework/Versions/3.10/lib/python3.10/site-packages/requests/sessions.py", line 701, in send
    r = adapter.send(request, **kwargs)
  File "/Library/Frameworks/Python.framework/Versions/3.10/lib/python3.10/site-packages/requests/adapters.py", line 578, in send
    raise ReadTimeout(e, request=request)
requests.exceptions.ReadTimeout: HTTPConnectionPool(host='127.0.0.1', port=8000): Read timed out. (read timeout=300)
2025-08-22 13:54:03,714 | INFO     | ‚è≥ Cadence report not ready (attempt 3/8) ‚Äì waiting 10s
2025-08-22 13:54:13,723 | INFO     | üì° Calling: http://127.0.0.1:8000/analytics/cadence/weekly-report?week_end=2025-08-17&ensure_snapshot=true&persist_front_door=true ‚Äì Cadence weekly-report
2025-08-22 13:59:13,734 | ERROR    | ‚ùå Error calling Cadence weekly-report: HTTPConnectionPool(host='127.0.0.1', port=8000): Read timed out. (read timeout=300)
Traceback (most recent call last):
  File "/Library/Frameworks/Python.framework/Versions/3.10/lib/python3.10/site-packages/urllib3/connectionpool.py", line 449, in _make_request
    six.raise_from(e, None)
  File "<string>", line 3, in raise_from
  File "/Library/Frameworks/Python.framework/Versions/3.10/lib/python3.10/site-packages/urllib3/connectionpool.py", line 444, in _make_request
    httplib_response = conn.getresponse()
  File "/Library/Frameworks/Python.framework/Versions/3.10/lib/python3.10/http/client.py", line 1374, in getresponse
    response.begin()
  File "/Library/Frameworks/Python.framework/Versions/3.10/lib/python3.10/http/client.py", line 318, in begin
    version, status, reason = self._read_status()
  File "/Library/Frameworks/Python.framework/Versions/3.10/lib/python3.10/http/client.py", line 279, in _read_status
    line = str(self.fp.readline(_MAXLINE + 1), "iso-8859-1")
  File "/Library/Frameworks/Python.framework/Versions/3.10/lib/python3.10/socket.py", line 705, in readinto
    return self._sock.recv_into(b)
TimeoutError: timed out

During handling of the above exception, another exception occurred:

Traceback (most recent call last):
  File "/Library/Frameworks/Python.framework/Versions/3.10/lib/python3.10/site-packages/requests/adapters.py", line 489, in send
    resp = conn.urlopen(
  File "/Library/Frameworks/Python.framework/Versions/3.10/lib/python3.10/site-packages/urllib3/connectionpool.py", line 787, in urlopen
    retries = retries.increment(
  File "/Library/Frameworks/Python.framework/Versions/3.10/lib/python3.10/site-packages/urllib3/util/retry.py", line 550, in increment
    raise six.reraise(type(error), error, _stacktrace)
  File "/Library/Frameworks/Python.framework/Versions/3.10/lib/python3.10/site-packages/urllib3/packages/six.py", line 770, in reraise
    raise value
  File "/Library/Frameworks/Python.framework/Versions/3.10/lib/python3.10/site-packages/urllib3/connectionpool.py", line 703, in urlopen
    httplib_response = self._make_request(
  File "/Library/Frameworks/Python.framework/Versions/3.10/lib/python3.10/site-packages/urllib3/connectionpool.py", line 451, in _make_request
    self._raise_timeout(err=e, url=url, timeout_value=read_timeout)
  File "/Library/Frameworks/Python.framework/Versions/3.10/lib/python3.10/site-packages/urllib3/connectionpool.py", line 340, in _raise_timeout
    raise ReadTimeoutError(
urllib3.exceptions.ReadTimeoutError: HTTPConnectionPool(host='127.0.0.1', port=8000): Read timed out. (read timeout=300)

During handling of the above exception, another exception occurred:

Traceback (most recent call last):
  File "/Users/joshuamontoya/np-analytics-app/run_jobs.py", line 52, in call_job
    r = requests.get(url, timeout=timeout)
  File "/Library/Frameworks/Python.framework/Versions/3.10/lib/python3.10/site-packages/requests/api.py", line 73, in get
    return request("get", url, params=params, **kwargs)
  File "/Library/Frameworks/Python.framework/Versions/3.10/lib/python3.10/site-packages/requests/api.py", line 59, in request
    return session.request(method=method, url=url, **kwargs)
  File "/Library/Frameworks/Python.framework/Versions/3.10/lib/python3.10/site-packages/requests/sessions.py", line 587, in request
    resp = self.send(prep, **send_kwargs)
  File "/Library/Frameworks/Python.framework/Versions/3.10/lib/python3.10/site-packages/requests/sessions.py", line 701, in send
    r = adapter.send(request, **kwargs)
  File "/Library/Frameworks/Python.framework/Versions/3.10/lib/python3.10/site-packages/requests/adapters.py", line 578, in send
    raise ReadTimeout(e, request=request)
requests.exceptions.ReadTimeout: HTTPConnectionPool(host='127.0.0.1', port=8000): Read timed out. (read timeout=300)
2025-08-22 13:59:13,737 | INFO     | ‚è≥ Cadence report not ready (attempt 4/8) ‚Äì waiting 10s
2025-08-22 13:59:23,747 | INFO     | üì° Calling: http://127.0.0.1:8000/analytics/cadence/weekly-report?week_end=2025-08-17&ensure_snapshot=true&persist_front_door=true ‚Äì Cadence weekly-report
2025-08-22 14:04:23,757 | ERROR    | ‚ùå Error calling Cadence weekly-report: HTTPConnectionPool(host='127.0.0.1', port=8000): Read timed out. (read timeout=300)
Traceback (most recent call last):
  File "/Library/Frameworks/Python.framework/Versions/3.10/lib/python3.10/site-packages/urllib3/connectionpool.py", line 449, in _make_request
    six.raise_from(e, None)
  File "<string>", line 3, in raise_from
  File "/Library/Frameworks/Python.framework/Versions/3.10/lib/python3.10/site-packages/urllib3/connectionpool.py", line 444, in _make_request
    httplib_response = conn.getresponse()
  File "/Library/Frameworks/Python.framework/Versions/3.10/lib/python3.10/http/client.py", line 1374, in getresponse
    response.begin()
  File "/Library/Frameworks/Python.framework/Versions/3.10/lib/python3.10/http/client.py", line 318, in begin
    version, status, reason = self._read_status()
  File "/Library/Frameworks/Python.framework/Versions/3.10/lib/python3.10/http/client.py", line 279, in _read_status
    line = str(self.fp.readline(_MAXLINE + 1), "iso-8859-1")
  File "/Library/Frameworks/Python.framework/Versions/3.10/lib/python3.10/socket.py", line 705, in readinto
    return self._sock.recv_into(b)
TimeoutError: timed out

During handling of the above exception, another exception occurred:

Traceback (most recent call last):
  File "/Library/Frameworks/Python.framework/Versions/3.10/lib/python3.10/site-packages/requests/adapters.py", line 489, in send
    resp = conn.urlopen(
  File "/Library/Frameworks/Python.framework/Versions/3.10/lib/python3.10/site-packages/urllib3/connectionpool.py", line 787, in urlopen
    retries = retries.increment(
  File "/Library/Frameworks/Python.framework/Versions/3.10/lib/python3.10/site-packages/urllib3/util/retry.py", line 550, in increment
    raise six.reraise(type(error), error, _stacktrace)
  File "/Library/Frameworks/Python.framework/Versions/3.10/lib/python3.10/site-packages/urllib3/packages/six.py", line 770, in reraise
    raise value
  File "/Library/Frameworks/Python.framework/Versions/3.10/lib/python3.10/site-packages/urllib3/connectionpool.py", line 703, in urlopen
    httplib_response = self._make_request(
  File "/Library/Frameworks/Python.framework/Versions/3.10/lib/python3.10/site-packages/urllib3/connectionpool.py", line 451, in _make_request
    self._raise_timeout(err=e, url=url, timeout_value=read_timeout)
  File "/Library/Frameworks/Python.framework/Versions/3.10/lib/python3.10/site-packages/urllib3/connectionpool.py", line 340, in _raise_timeout
    raise ReadTimeoutError(
urllib3.exceptions.ReadTimeoutError: HTTPConnectionPool(host='127.0.0.1', port=8000): Read timed out. (read timeout=300)

During handling of the above exception, another exception occurred:

Traceback (most recent call last):
  File "/Users/joshuamontoya/np-analytics-app/run_jobs.py", line 52, in call_job
    r = requests.get(url, timeout=timeout)
  File "/Library/Frameworks/Python.framework/Versions/3.10/lib/python3.10/site-packages/requests/api.py", line 73, in get
    return request("get", url, params=params, **kwargs)
  File "/Library/Frameworks/Python.framework/Versions/3.10/lib/python3.10/site-packages/requests/api.py", line 59, in request
    return session.request(method=method, url=url, **kwargs)
  File "/Library/Frameworks/Python.framework/Versions/3.10/lib/python3.10/site-packages/requests/sessions.py", line 587, in request
    resp = self.send(prep, **send_kwargs)
  File "/Library/Frameworks/Python.framework/Versions/3.10/lib/python3.10/site-packages/requests/sessions.py", line 701, in send
    r = adapter.send(request, **kwargs)
  File "/Library/Frameworks/Python.framework/Versions/3.10/lib/python3.10/site-packages/requests/adapters.py", line 578, in send
    raise ReadTimeout(e, request=request)
requests.exceptions.ReadTimeout: HTTPConnectionPool(host='127.0.0.1', port=8000): Read timed out. (read timeout=300)
2025-08-22 14:04:23,758 | INFO     | ‚è≥ Cadence report not ready (attempt 5/8) ‚Äì waiting 10s
2025-08-22 14:04:33,768 | INFO     | üì° Calling: http://127.0.0.1:8000/analytics/cadence/weekly-report?week_end=2025-08-17&ensure_snapshot=true&persist_front_door=true ‚Äì Cadence weekly-report
2025-08-22 14:09:33,778 | ERROR    | ‚ùå Error calling Cadence weekly-report: HTTPConnectionPool(host='127.0.0.1', port=8000): Read timed out. (read timeout=300)
Traceback (most recent call last):
  File "/Library/Frameworks/Python.framework/Versions/3.10/lib/python3.10/site-packages/urllib3/connectionpool.py", line 449, in _make_request
    six.raise_from(e, None)
  File "<string>", line 3, in raise_from
  File "/Library/Frameworks/Python.framework/Versions/3.10/lib/python3.10/site-packages/urllib3/connectionpool.py", line 444, in _make_request
    httplib_response = conn.getresponse()
  File "/Library/Frameworks/Python.framework/Versions/3.10/lib/python3.10/http/client.py", line 1374, in getresponse
    response.begin()
  File "/Library/Frameworks/Python.framework/Versions/3.10/lib/python3.10/http/client.py", line 318, in begin
    version, status, reason = self._read_status()
  File "/Library/Frameworks/Python.framework/Versions/3.10/lib/python3.10/http/client.py", line 279, in _read_status
    line = str(self.fp.readline(_MAXLINE + 1), "iso-8859-1")
  File "/Library/Frameworks/Python.framework/Versions/3.10/lib/python3.10/socket.py", line 705, in readinto
    return self._sock.recv_into(b)
TimeoutError: timed out

During handling of the above exception, another exception occurred:

Traceback (most recent call last):
  File "/Library/Frameworks/Python.framework/Versions/3.10/lib/python3.10/site-packages/requests/adapters.py", line 489, in send
    resp = conn.urlopen(
  File "/Library/Frameworks/Python.framework/Versions/3.10/lib/python3.10/site-packages/urllib3/connectionpool.py", line 787, in urlopen
    retries = retries.increment(
  File "/Library/Frameworks/Python.framework/Versions/3.10/lib/python3.10/site-packages/urllib3/util/retry.py", line 550, in increment
    raise six.reraise(type(error), error, _stacktrace)
  File "/Library/Frameworks/Python.framework/Versions/3.10/lib/python3.10/site-packages/urllib3/packages/six.py", line 770, in reraise
    raise value
  File "/Library/Frameworks/Python.framework/Versions/3.10/lib/python3.10/site-packages/urllib3/connectionpool.py", line 703, in urlopen
    httplib_response = self._make_request(
  File "/Library/Frameworks/Python.framework/Versions/3.10/lib/python3.10/site-packages/urllib3/connectionpool.py", line 451, in _make_request
    self._raise_timeout(err=e, url=url, timeout_value=read_timeout)
  File "/Library/Frameworks/Python.framework/Versions/3.10/lib/python3.10/site-packages/urllib3/connectionpool.py", line 340, in _raise_timeout
    raise ReadTimeoutError(
urllib3.exceptions.ReadTimeoutError: HTTPConnectionPool(host='127.0.0.1', port=8000): Read timed out. (read timeout=300)

During handling of the above exception, another exception occurred:

Traceback (most recent call last):
  File "/Users/joshuamontoya/np-analytics-app/run_jobs.py", line 52, in call_job
    r = requests.get(url, timeout=timeout)
  File "/Library/Frameworks/Python.framework/Versions/3.10/lib/python3.10/site-packages/requests/api.py", line 73, in get
    return request("get", url, params=params, **kwargs)
  File "/Library/Frameworks/Python.framework/Versions/3.10/lib/python3.10/site-packages/requests/api.py", line 59, in request
    return session.request(method=method, url=url, **kwargs)
  File "/Library/Frameworks/Python.framework/Versions/3.10/lib/python3.10/site-packages/requests/sessions.py", line 587, in request
    resp = self.send(prep, **send_kwargs)
  File "/Library/Frameworks/Python.framework/Versions/3.10/lib/python3.10/site-packages/requests/sessions.py", line 701, in send
    r = adapter.send(request, **kwargs)
  File "/Library/Frameworks/Python.framework/Versions/3.10/lib/python3.10/site-packages/requests/adapters.py", line 578, in send
    raise ReadTimeout(e, request=request)
requests.exceptions.ReadTimeout: HTTPConnectionPool(host='127.0.0.1', port=8000): Read timed out. (read timeout=300)
2025-08-22 14:09:33,782 | INFO     | ‚è≥ Cadence report not ready (attempt 6/8) ‚Äì waiting 10s
2025-08-22 14:09:43,793 | INFO     | üì° Calling: http://127.0.0.1:8000/analytics/cadence/weekly-report?week_end=2025-08-17&ensure_snapshot=true&persist_front_door=true ‚Äì Cadence weekly-report
2025-08-22 14:14:43,798 | ERROR    | ‚ùå Error calling Cadence weekly-report: HTTPConnectionPool(host='127.0.0.1', port=8000): Read timed out. (read timeout=300)
Traceback (most recent call last):
  File "/Library/Frameworks/Python.framework/Versions/3.10/lib/python3.10/site-packages/urllib3/connectionpool.py", line 449, in _make_request
    six.raise_from(e, None)
  File "<string>", line 3, in raise_from
  File "/Library/Frameworks/Python.framework/Versions/3.10/lib/python3.10/site-packages/urllib3/connectionpool.py", line 444, in _make_request
    httplib_response = conn.getresponse()
  File "/Library/Frameworks/Python.framework/Versions/3.10/lib/python3.10/http/client.py", line 1374, in getresponse
    response.begin()
  File "/Library/Frameworks/Python.framework/Versions/3.10/lib/python3.10/http/client.py", line 318, in begin
    version, status, reason = self._read_status()
  File "/Library/Frameworks/Python.framework/Versions/3.10/lib/python3.10/http/client.py", line 279, in _read_status
    line = str(self.fp.readline(_MAXLINE + 1), "iso-8859-1")
  File "/Library/Frameworks/Python.framework/Versions/3.10/lib/python3.10/socket.py", line 705, in readinto
    return self._sock.recv_into(b)
TimeoutError: timed out

During handling of the above exception, another exception occurred:

Traceback (most recent call last):
  File "/Library/Frameworks/Python.framework/Versions/3.10/lib/python3.10/site-packages/requests/adapters.py", line 489, in send
    resp = conn.urlopen(
  File "/Library/Frameworks/Python.framework/Versions/3.10/lib/python3.10/site-packages/urllib3/connectionpool.py", line 787, in urlopen
    retries = retries.increment(
  File "/Library/Frameworks/Python.framework/Versions/3.10/lib/python3.10/site-packages/urllib3/util/retry.py", line 550, in increment
    raise six.reraise(type(error), error, _stacktrace)
  File "/Library/Frameworks/Python.framework/Versions/3.10/lib/python3.10/site-packages/urllib3/packages/six.py", line 770, in reraise
    raise value
  File "/Library/Frameworks/Python.framework/Versions/3.10/lib/python3.10/site-packages/urllib3/connectionpool.py", line 703, in urlopen
    httplib_response = self._make_request(
  File "/Library/Frameworks/Python.framework/Versions/3.10/lib/python3.10/site-packages/urllib3/connectionpool.py", line 451, in _make_request
    self._raise_timeout(err=e, url=url, timeout_value=read_timeout)
  File "/Library/Frameworks/Python.framework/Versions/3.10/lib/python3.10/site-packages/urllib3/connectionpool.py", line 340, in _raise_timeout
    raise ReadTimeoutError(
urllib3.exceptions.ReadTimeoutError: HTTPConnectionPool(host='127.0.0.1', port=8000): Read timed out. (read timeout=300)

During handling of the above exception, another exception occurred:

Traceback (most recent call last):
  File "/Users/joshuamontoya/np-analytics-app/run_jobs.py", line 52, in call_job
    r = requests.get(url, timeout=timeout)
  File "/Library/Frameworks/Python.framework/Versions/3.10/lib/python3.10/site-packages/requests/api.py", line 73, in get
    return request("get", url, params=params, **kwargs)
  File "/Library/Frameworks/Python.framework/Versions/3.10/lib/python3.10/site-packages/requests/api.py", line 59, in request
    return session.request(method=method, url=url, **kwargs)
  File "/Library/Frameworks/Python.framework/Versions/3.10/lib/python3.10/site-packages/requests/sessions.py", line 587, in request
    resp = self.send(prep, **send_kwargs)
  File "/Library/Frameworks/Python.framework/Versions/3.10/lib/python3.10/site-packages/requests/sessions.py", line 701, in send
    r = adapter.send(request, **kwargs)
  File "/Library/Frameworks/Python.framework/Versions/3.10/lib/python3.10/site-packages/requests/adapters.py", line 578, in send
    raise ReadTimeout(e, request=request)
requests.exceptions.ReadTimeout: HTTPConnectionPool(host='127.0.0.1', port=8000): Read timed out. (read timeout=300)
2025-08-22 14:14:43,801 | INFO     | ‚è≥ Cadence report not ready (attempt 7/8) ‚Äì waiting 10s
2025-08-22 14:14:53,803 | INFO     | üì° Calling: http://127.0.0.1:8000/analytics/cadence/weekly-report?week_end=2025-08-17&ensure_snapshot=true&persist_front_door=true ‚Äì Cadence weekly-report
2025-08-22 14:19:53,811 | ERROR    | ‚ùå Error calling Cadence weekly-report: HTTPConnectionPool(host='127.0.0.1', port=8000): Read timed out. (read timeout=300)
Traceback (most recent call last):
  File "/Library/Frameworks/Python.framework/Versions/3.10/lib/python3.10/site-packages/urllib3/connectionpool.py", line 449, in _make_request
    six.raise_from(e, None)
  File "<string>", line 3, in raise_from
  File "/Library/Frameworks/Python.framework/Versions/3.10/lib/python3.10/site-packages/urllib3/connectionpool.py", line 444, in _make_request
    httplib_response = conn.getresponse()
  File "/Library/Frameworks/Python.framework/Versions/3.10/lib/python3.10/http/client.py", line 1374, in getresponse
    response.begin()
  File "/Library/Frameworks/Python.framework/Versions/3.10/lib/python3.10/http/client.py", line 318, in begin
    version, status, reason = self._read_status()
  File "/Library/Frameworks/Python.framework/Versions/3.10/lib/python3.10/http/client.py", line 279, in _read_status
    line = str(self.fp.readline(_MAXLINE + 1), "iso-8859-1")
  File "/Library/Frameworks/Python.framework/Versions/3.10/lib/python3.10/socket.py", line 705, in readinto
    return self._sock.recv_into(b)
TimeoutError: timed out

During handling of the above exception, another exception occurred:

Traceback (most recent call last):
  File "/Library/Frameworks/Python.framework/Versions/3.10/lib/python3.10/site-packages/requests/adapters.py", line 489, in send
    resp = conn.urlopen(
  File "/Library/Frameworks/Python.framework/Versions/3.10/lib/python3.10/site-packages/urllib3/connectionpool.py", line 787, in urlopen
    retries = retries.increment(
  File "/Library/Frameworks/Python.framework/Versions/3.10/lib/python3.10/site-packages/urllib3/util/retry.py", line 550, in increment
    raise six.reraise(type(error), error, _stacktrace)
  File "/Library/Frameworks/Python.framework/Versions/3.10/lib/python3.10/site-packages/urllib3/packages/six.py", line 770, in reraise
    raise value
  File "/Library/Frameworks/Python.framework/Versions/3.10/lib/python3.10/site-packages/urllib3/connectionpool.py", line 703, in urlopen
    httplib_response = self._make_request(
  File "/Library/Frameworks/Python.framework/Versions/3.10/lib/python3.10/site-packages/urllib3/connectionpool.py", line 451, in _make_request
    self._raise_timeout(err=e, url=url, timeout_value=read_timeout)
  File "/Library/Frameworks/Python.framework/Versions/3.10/lib/python3.10/site-packages/urllib3/connectionpool.py", line 340, in _raise_timeout
    raise ReadTimeoutError(
urllib3.exceptions.ReadTimeoutError: HTTPConnectionPool(host='127.0.0.1', port=8000): Read timed out. (read timeout=300)

During handling of the above exception, another exception occurred:

Traceback (most recent call last):
  File "/Users/joshuamontoya/np-analytics-app/run_jobs.py", line 52, in call_job
    r = requests.get(url, timeout=timeout)
  File "/Library/Frameworks/Python.framework/Versions/3.10/lib/python3.10/site-packages/requests/api.py", line 73, in get
    return request("get", url, params=params, **kwargs)
  File "/Library/Frameworks/Python.framework/Versions/3.10/lib/python3.10/site-packages/requests/api.py", line 59, in request
    return session.request(method=method, url=url, **kwargs)
  File "/Library/Frameworks/Python.framework/Versions/3.10/lib/python3.10/site-packages/requests/sessions.py", line 587, in request
    resp = self.send(prep, **send_kwargs)
  File "/Library/Frameworks/Python.framework/Versions/3.10/lib/python3.10/site-packages/requests/sessions.py", line 701, in send
    r = adapter.send(request, **kwargs)
  File "/Library/Frameworks/Python.framework/Versions/3.10/lib/python3.10/site-packages/requests/adapters.py", line 578, in send
    raise ReadTimeout(e, request=request)
requests.exceptions.ReadTimeout: HTTPConnectionPool(host='127.0.0.1', port=8000): Read timed out. (read timeout=300)
2025-08-22 14:19:53,812 | INFO     | ‚è≥ Cadence report not ready (attempt 8/8) ‚Äì waiting 10s
2025-08-22 14:20:03,822 | WARNING  | ‚ö†Ô∏è Cadence report missing sections after 8 attempts; proceeding with best effort.
2025-08-22 14:20:03,823 | INFO     | üì° Calling: http://127.0.0.1:8000/attendance/process-sheet ‚Äì Adult attendance processing
2025-08-22 14:20:05,490 | INFO     | ‚úÖ Finished: Adult attendance processing (200)
2025-08-22 14:20:06,500 | INFO     | üì° Calling: http://127.0.0.1:8000/planning-center/checkins ‚Äì Planning Center check-ins
2025-08-22 14:21:26,723 | INFO     | ‚úÖ Finished: Planning Center check-ins (200)
2025-08-22 14:21:27,730 | INFO     | üì° Calling: http://127.0.0.1:8000/planning-center/giving/weekly-summary ‚Äì Planning Center Giving Summary
2025-08-22 14:21:41,324 | INFO     | ‚úÖ Finished: Planning Center Giving Summary (200)
2025-08-22 14:21:42,326 | INFO     | üì° Calling: http://127.0.0.1:8000/planning-center/groups ‚Äì Planning Center Groups
2025-08-22 14:22:02,751 | INFO     | ‚úÖ Finished: Planning Center Groups (200)
2025-08-22 14:22:03,760 | INFO     | üì° Calling: http://127.0.0.1:8000/planning-center/serving/summary ‚Äì Planning Center Volunteer Summary
2025-08-22 14:22:05,737 | INFO     | ‚úÖ Finished: Planning Center Volunteer Summary (200)
2025-08-22 14:22:06,738 | INFO     | üì° Calling: http://127.0.0.1:8000/youtube/weekly-summary ‚Äì YouTube weekly summary
2025-08-22 14:22:08,307 | INFO     | ‚úÖ Finished: YouTube weekly summary (200)
2025-08-22 14:22:09,309 | INFO     | üì° Calling: http://127.0.0.1:8000/youtube/livestreams ‚Äì YouTube livestream tracking
2025-08-22 14:22:11,394 | INFO     | ‚úÖ Finished: YouTube livestream tracking (200)
2025-08-22 14:22:12,398 | INFO     | üì° Calling: http://127.0.0.1:8000/mailchimp/weekly-summary ‚Äì Mailchimp weekly summary
2025-08-22 14:22:18,722 | INFO     | ‚úÖ Finished: Mailchimp weekly summary (200)
2025-08-22 14:22:19,732 | INFO     | üß† Assistant input:
You are NP Analytics‚Äô reporting assistant.
Compose a clear, concise weekly update for the team. Use the sections below in THIS EXACT ORDER.
Rules:
- Use short headings and 2‚Äì4 bullet points per section.
- Keep numbers accurate; do not invent fields.
- If a section is missing, write ‚ÄúNo data this week.‚Äù
- Keep it readable for non-technical staff.

### Adult Attendance Summary
```json
{
  "status": "done",
  "processed_rows": 0,
  "summary": []
}
```
### Check-ins (Kids & Students Attendance Summaries)
```json
{
  "status": "success",
  "date": "2025-08-17",
  "checkins_count": 678,
  "person_facts_attempted": 678,
  "person_facts_inserted": 678,
  "breakdown": {
    "InsideOut": {
      "attendance_1630": 207,
      "total_attendance": 207,
      "grade_10_male": 29,
      "grade_12_male": 26,
      "grade_9_female": 30,
      "grade_12_female": 26,
      "grade_10_female": 43,
      "grade_11_male": 14,
      "new_kids_1630": 4,
      "new_students": 4,
      "grade_9_male": 20,
      ‚Ä¶
üß† Assistant input: You are NP Analytics‚Äô reporting assistant.
Compose a clear, concise weekly update for the team. Use the sections below in THIS EXACT ORDER.
Rules:
- Use short headings and 2‚Äì4 bullet points per section.
- Keep numbers accurate; do not invent fields.
- If a section is missing, write ‚ÄúNo data this week.‚Äù
- Keep it readable for non-technical staff.

### Adult Attendance Summary
```json
{
  "status": "done",
  "processed_rows": 0,
  "summary": []
}
```
### Check-ins (Kids & Students Attendance Summaries)
```json
{
  "status": "success",
  "date": "2025-08-17",
  "checkins_count": 678,
  "person_facts_attempted": 678,
  "person_facts_inserted": 678,
  "breakdown": {
    "InsideOut": {
      "attendance_1630": 207,
      "total_attendance": 207,
      "grade_10_male": 29,
      "grade_12_male": 26,
      "grade_9_female": 30,
      "grade_12_female": 26,
      "grade_10_female": 43,
      "grade_11_male": 14,
      "new_kids_1630": 4,
      "new_students": 4,
      "grade_9_male": 20,
      "grade_11_female": 11,
      "grade_9_other": 1,
      "date": "2025-08-17"
    },
    "Transit": {
      "attendance_1630": 5,
      "total_attendance": 150,
      "grade_8_other": 2,
      "grade_8_female": 41,
      "grade_8_male": 20,
      "attendance_1100": 76,
      "grade_6_male": 21,
      "grade_7_male": 16,
      "grade_6_female": 26,
      "grade_7_female": 23,
      "new_kids_1100": 2,
      "total_new_kids": 4,
      "attendance_930": 69,
      "new_kids_930": 2,
      "date": "2025-08-17"
    },
    "Waumba Land": {
      "attendance_1100": 27,
      "total_attendance": 74,
      "age_3_5_female": 29,
      "age_0_2_male": 12,
      "age_3_5_male": 22,
      "new_kids_1100": 1,
      "total_new_kids": 3,
      "age_3_5_m": 2,
      "attendance_930": 47,
      "age_0_2_female": 7,
      "new_kids_930": 2,
      "age_3_5_other": 1,
      "age_0_2_other": 1,
      "date": "2025-08-17"
    },
    "UpStreet": {
      "attendance_1100": 123,
      "total_attendance": 247,
      "grade_k_1_female": 34,
      "new_kids_1100": 2,
      "total_new_kids": 5,
      "grade_k_1_male": 36,
      "grade_4_5_female": 43,
      "grade_4_5_male": 53,
      "grade_2_3_male": 43,
      "grade_2_3_female": 36,
      "grade_k_1_other": 1,
      "grade_4_5_other": 1,
      "attendance_930": 124,
      "new_kids_930": 3,
      "date": "2025-08-17"
    }
  },
  "uncounted_reasons": {
    "no_person": 1,
    "no_person_data": 0,
    "no_event": 0,
    "no_event_time": 0,
    "no_ministry": 0,
    "no_service_time": 0,
    "duplicate_checkin": 0
  },
  "skip_details": [],
  "possible_duplicates": {}
}
```
### Giving Summary
```json
{
  "status": "success",
  "week_start": "2025-08-11",
  "week_end": "2025-08-17",
  "total_giving": 43818.27,
  "giving_units": 108,
  "mode": "gross",
  "date_field": "received_at"
}
```
### Volunteering Summary
```json
{
  "status": "ok",
  "week_end": "2025-08-17",
  "total_active_volunteers": 606,
  "volunteers_by_category": {
    "Groups": 183,
    "InsideOut": 117,
    "Transit": 66,
    "UpStreet": 226,
    "Waumba Land": 131,
    "Misc": 82
  },
  "persisted": true
}
```
### Groups Summary
```json
{
  "status": "success",
  "date": "2025-08-22",
  "metrics": {
    "number_of_groups": 85,
    "total_groups_attendance": 613,
    "group_leaders": 124,
    "coaches": 20
  },
  "distinct_group_count": 85,
  "total_groups_attendance": 613,
  "group_leaders": 124,
  "coaches": 20
}
```
### Engaged Summary
```json
{
  "note": "no engaged data"
}
```
### Front Door Summary
```json
{
  "note": "no front door data"
}
```
### YouTube Livestreams Summary
```json
{
  "status": "saved",
  "summary": {
    "week_start": "2025-08-11",
    "week_end": "2025-08-17",
    "avg_watch_duration": 360,
    "total_views": 1036,
    "subscribers_gained": 13,
    "subscribers_lost": 3,
    "net_subscribers": 10
  }
}
```
2025-08-22 14:22:20,383 | INFO     | HTTP Request: POST https://api.openai.com/v1/threads "HTTP/1.1 200 OK"
2025-08-22 14:22:21,094 | INFO     | HTTP Request: POST https://api.openai.com/v1/threads/thread_5HM26DFYXXuG0GCsbYFiCfi5/messages "HTTP/1.1 200 OK"
2025-08-22 14:22:22,121 | INFO     | HTTP Request: POST https://api.openai.com/v1/threads/thread_5HM26DFYXXuG0GCsbYFiCfi5/runs "HTTP/1.1 200 OK"
2025-08-22 14:22:22,530 | INFO     | HTTP Request: GET https://api.openai.com/v1/threads/thread_5HM26DFYXXuG0GCsbYFiCfi5/runs/run_JnFe6qKOJL2ShbuDsHeqy0Hh "HTTP/1.1 200 OK"
2025-08-22 14:22:24,577 | INFO     | HTTP Request: GET https://api.openai.com/v1/threads/thread_5HM26DFYXXuG0GCsbYFiCfi5/runs/run_JnFe6qKOJL2ShbuDsHeqy0Hh "HTTP/1.1 200 OK"
2025-08-22 14:22:25,907 | INFO     | HTTP Request: GET https://api.openai.com/v1/threads/thread_5HM26DFYXXuG0GCsbYFiCfi5/runs/run_JnFe6qKOJL2ShbuDsHeqy0Hh "HTTP/1.1 200 OK"
2025-08-22 14:22:28,951 | INFO     | HTTP Request: GET https://api.openai.com/v1/threads/thread_5HM26DFYXXuG0GCsbYFiCfi5/runs/run_JnFe6qKOJL2ShbuDsHeqy0Hh "HTTP/1.1 200 OK"
2025-08-22 14:22:30,222 | INFO     | HTTP Request: GET https://api.openai.com/v1/threads/thread_5HM26DFYXXuG0GCsbYFiCfi5/runs/run_JnFe6qKOJL2ShbuDsHeqy0Hh "HTTP/1.1 200 OK"
2025-08-22 14:22:31,484 | INFO     | HTTP Request: GET https://api.openai.com/v1/threads/thread_5HM26DFYXXuG0GCsbYFiCfi5/runs/run_JnFe6qKOJL2ShbuDsHeqy0Hh "HTTP/1.1 200 OK"
2025-08-22 14:22:32,872 | INFO     | HTTP Request: GET https://api.openai.com/v1/threads/thread_5HM26DFYXXuG0GCsbYFiCfi5/runs/run_JnFe6qKOJL2ShbuDsHeqy0Hh "HTTP/1.1 200 OK"
2025-08-22 14:22:34,410 | INFO     | HTTP Request: GET https://api.openai.com/v1/threads/thread_5HM26DFYXXuG0GCsbYFiCfi5/runs/run_JnFe6qKOJL2ShbuDsHeqy0Hh "HTTP/1.1 200 OK"
2025-08-22 14:22:34,583 | INFO     | HTTP Request: GET https://api.openai.com/v1/threads/thread_5HM26DFYXXuG0GCsbYFiCfi5/messages "HTTP/1.1 200 OK"
üß† Assistant finished in 14.85 s
2025-08-22 14:22:34,586 | INFO     | üß† Assistant finished
2025-08-22 14:22:36,876 | INFO     | üì§ Posted team summary to channel 1axdre-98673
2025-08-22 14:22:36,876 | INFO     | üì§ Sent 0 DM message(s) to ['57047850']
                                                                                                                           
joshuamontoya@MacBookPro ~/np-analytics-app                                                                     [14:22:37] 
> $                                       




INFO:     127.0.0.1:60674 - "GET /docs HTTP/1.1" 200 OK
2025-08-22 13:16:37,155 INFO app.planning_center.people: [people] sync starting since=None per_page=200 batch_pages=5
2025-08-22 13:16:37,790 INFO app.planning_center.people: [people] page=1 items=100 included=33
2025-08-22 13:16:38,460 INFO app.planning_center.people: [people] page=2 items=100 included=25
2025-08-22 13:16:39,192 INFO app.planning_center.people: [people] page=3 items=100 included=33
2025-08-22 13:16:39,795 INFO app.planning_center.people: [people] page=4 items=100 included=25
2025-08-22 13:16:40,412 INFO app.planning_center.people: [people] page=5 items=100 included=30
2025-08-22 13:17:53,980 INFO app.planning_center.people: [people] committed batch upserts hh=129 ppl=500 totals hh=129 ppl=500 pages=5 elapsed=78.5s
2025-08-22 13:17:54,662 INFO app.planning_center.people: [people] page=6 items=100 included=40
2025-08-22 13:17:55,054 INFO app.planning_center.people: [people] page=7 items=100 included=39
2025-08-22 13:17:55,582 INFO app.planning_center.people: [people] page=8 items=100 included=36
2025-08-22 13:17:56,127 INFO app.planning_center.people: [people] page=9 items=100 included=43
2025-08-22 13:17:56,703 INFO app.planning_center.people: [people] page=10 items=100 included=36
2025-08-22 13:19:09,724 INFO app.planning_center.people: [people] committed batch upserts hh=182 ppl=500 totals hh=311 ppl=1000 pages=10 elapsed=154.3s
2025-08-22 13:19:10,236 INFO app.planning_center.people: [people] page=11 items=100 included=41
2025-08-22 13:19:10,832 INFO app.planning_center.people: [people] page=12 items=100 included=43
2025-08-22 13:19:11,260 INFO app.planning_center.people: [people] page=13 items=100 included=45
2025-08-22 13:19:11,886 INFO app.planning_center.people: [people] page=14 items=100 included=35
2025-08-22 13:19:12,476 INFO app.planning_center.people: [people] page=15 items=100 included=42
2025-08-22 13:20:24,220 INFO app.planning_center.people: [people] committed batch upserts hh=175 ppl=500 totals hh=486 ppl=1500 pages=15 elapsed=228.8s
2025-08-22 13:20:24,775 INFO app.planning_center.people: [people] page=16 items=100 included=43
2025-08-22 13:20:25,510 INFO app.planning_center.people: [people] page=17 items=100 included=56
2025-08-22 13:20:26,109 INFO app.planning_center.people: [people] page=18 items=100 included=58
2025-08-22 13:20:26,822 INFO app.planning_center.people: [people] page=19 items=100 included=39
2025-08-22 13:20:27,436 INFO app.planning_center.people: [people] page=20 items=100 included=63
2025-08-22 13:21:37,881 INFO app.planning_center.groups: [groups] sync starting since=None per_page=100
2025-08-22 13:21:43,829 INFO app.planning_center.people: [people] committed batch upserts hh=231 ppl=500 totals hh=717 ppl=2000 pages=20 elapsed=308.4s
2025-08-22 13:21:44,317 INFO app.planning_center.people: [people] page=21 items=100 included=40
2025-08-22 13:21:44,866 INFO app.planning_center.people: [people] page=22 items=100 included=39
2025-08-22 13:21:45,551 INFO app.planning_center.people: [people] page=23 items=100 included=63
2025-08-22 13:21:46,030 INFO app.planning_center.people: [people] page=24 items=100 included=61
2025-08-22 13:21:46,442 INFO app.planning_center.people: [people] page=25 items=100 included=47
2025-08-22 13:22:08,483 WARNING app.planning_center.groups: [groups] memberships: skipping 1 rows due to missing people (FK). Seen=1080, existing=1079
2025-08-22 13:23:10,912 INFO app.planning_center.people: [people] committed batch upserts hh=229 ppl=500 totals hh=946 ppl=2500 pages=25 elapsed=395.4s
2025-08-22 13:23:11,404 INFO app.planning_center.people: [people] page=26 items=100 included=50
2025-08-22 13:23:11,958 INFO app.planning_center.people: [people] page=27 items=100 included=43
2025-08-22 13:23:12,516 INFO app.planning_center.people: [people] page=28 items=100 included=40
2025-08-22 13:23:13,036 INFO app.planning_center.people: [people] page=29 items=100 included=45
2025-08-22 13:23:13,692 INFO app.planning_center.people: [people] page=30 items=100 included=46
2025-08-22 13:24:30,852 INFO app.planning_center.people: [people] committed batch upserts hh=202 ppl=500 totals hh=1148 ppl=3000 pages=30 elapsed=475.4s
2025-08-22 13:24:31,516 INFO app.planning_center.people: [people] page=31 items=100 included=49
2025-08-22 13:24:32,138 INFO app.planning_center.people: [people] page=32 items=100 included=41
2025-08-22 13:24:32,602 INFO app.planning_center.people: [people] page=33 items=100 included=43
2025-08-22 13:24:33,064 INFO app.planning_center.people: [people] page=34 items=100 included=54
2025-08-22 13:24:33,490 INFO app.planning_center.people: [people] page=35 items=100 included=50
2025-08-22 13:25:36,449 INFO app.planning_center.groups: [groups] page=1 in 237.82s groups=100 memberships_rows=1774 (totals: groups=100 memberships=1774)
2025-08-22 13:25:51,558 INFO app.planning_center.people: [people] committed batch upserts hh=212 ppl=500 totals hh=1360 ppl=3500 pages=35 elapsed=556.1s
2025-08-22 13:25:52,124 INFO app.planning_center.people: [people] page=36 items=100 included=49
2025-08-22 13:25:52,592 INFO app.planning_center.people: [people] page=37 items=100 included=46
2025-08-22 13:25:53,150 INFO app.planning_center.people: [people] page=38 items=100 included=54
2025-08-22 13:25:53,641 INFO app.planning_center.people: [people] page=39 items=100 included=52
2025-08-22 13:25:54,233 INFO app.planning_center.people: [people] page=40 items=100 included=47
2025-08-22 13:26:06,093 WARNING app.planning_center.groups: [groups] memberships: skipping 4 rows due to missing people (FK). Seen=954, existing=950
2025-08-22 13:26:39,319 INFO app.planning_center.serving: [serving] sync starting since=None per_page=100 include_types=['Teams'] include_subs=None
2025-08-22 13:27:07,779 INFO app.planning_center.people: [people] committed batch upserts hh=219 ppl=500 totals hh=1579 ppl=4000 pages=40 elapsed=632.3s
2025-08-22 13:27:08,289 INFO app.planning_center.people: [people] page=41 items=100 included=56
2025-08-22 13:27:08,860 INFO app.planning_center.people: [people] page=42 items=100 included=55
2025-08-22 13:27:09,400 INFO app.planning_center.people: [people] page=43 items=100 included=46
2025-08-22 13:27:09,852 INFO app.planning_center.people: [people] page=44 items=100 included=42
2025-08-22 13:27:10,405 INFO app.planning_center.people: [people] page=45 items=100 included=50
2025-08-22 13:27:43,734 INFO app.planning_center.serving: [serving] page=1 in 63.77s groups=20 memberships_rows=544 (totals: groups=20 memberships=544)
2025-08-22 13:28:25,007 INFO app.planning_center.people: [people] committed batch upserts hh=220 ppl=500 totals hh=1799 ppl=4500 pages=45 elapsed=709.5s
2025-08-22 13:28:25,526 INFO app.planning_center.people: [people] page=46 items=100 included=47
2025-08-22 13:28:26,032 INFO app.planning_center.people: [people] page=47 items=100 included=44
2025-08-22 13:28:26,532 INFO app.planning_center.people: [people] page=48 items=100 included=51
2025-08-22 13:28:27,074 INFO app.planning_center.people: [people] page=49 items=100 included=76
2025-08-22 13:28:27,734 INFO app.planning_center.people: [people] page=50 items=100 included=85
2025-08-22 13:28:50,524 INFO app.planning_center.groups: [groups] page=2 in 193.45s groups=91 memberships_rows=1515 (totals: groups=191 memberships=3289)
2025-08-22 13:28:50,525 INFO app.planning_center.groups: [groups] sync complete pages=2 groups_upserted=191 memberships_upserted=3289
2025-08-22 13:29:22,887 INFO app.planning_center.serving: [serving] page=2 in 98.53s groups=9 memberships_rows=323 (totals: groups=29 memberships=867)
2025-08-22 13:29:22,888 INFO app.planning_center.serving: [serving] sync complete pages=2 groups_upserted=29 memberships_upserted=867
INFO:     127.0.0.1:60957 - "GET /planning-center/serving/sync HTTP/1.1" 200 OK
2025-08-22 13:29:47,394 INFO app.planning_center.people: [people] committed batch upserts hh=292 ppl=500 totals hh=2091 ppl=5000 pages=50 elapsed=791.9s
2025-08-22 13:29:48,272 INFO app.planning_center.people: [people] page=51 items=100 included=71
2025-08-22 13:29:48,879 INFO app.planning_center.people: [people] page=52 items=100 included=44
2025-08-22 13:29:49,408 INFO app.planning_center.people: [people] page=53 items=100 included=49
2025-08-22 13:29:50,028 INFO app.planning_center.people: [people] page=54 items=100 included=48
2025-08-22 13:29:50,482 INFO app.planning_center.people: [people] page=55 items=100 included=51
2025-08-22 13:30:45,741 INFO app.planning_center.checkins: [checkins] f_checkins_person attempted=678 affected=678 for 2025-08-17
INFO:     127.0.0.1:61014 - "GET /planning-center/checkins?date=2025-08-17 HTTP/1.1" 200 OK
2025-08-22 13:30:59,839 INFO app.planning_center.giving: [giving] f_giving_person_week upserted=108 for week_end=2025-08-17 (donors=108)
INFO:     127.0.0.1:61036 - "GET /planning-center/giving/weekly-summary HTTP/1.1" 200 OK
2025-08-22 13:31:08,025 INFO app.planning_center.people: [people] committed batch upserts hh=240 ppl=500 totals hh=2331 ppl=5500 pages=55 elapsed=872.6s
2025-08-22 13:31:08,629 INFO app.planning_center.people: [people] page=56 items=100 included=54
2025-08-22 13:31:09,254 INFO app.planning_center.people: [people] page=57 items=100 included=45
2025-08-22 13:31:09,828 INFO app.planning_center.people: [people] page=58 items=100 included=48
2025-08-22 13:31:10,481 INFO app.planning_center.people: [people] page=59 items=100 included=47
2025-08-22 13:31:11,126 INFO app.planning_center.people: [people] page=60 items=100 included=49
2025-08-22 13:32:26,213 INFO app.cadence: [cadence] attend upserted=644 people=644 (window=180d, IO excluded)
2025-08-22 13:32:26,879 INFO app.planning_center.people: [people] committed batch upserts hh=210 ppl=500 totals hh=2541 ppl=6000 pages=60 elapsed=951.4s
2025-08-22 13:32:27,542 INFO app.planning_center.people: [people] page=61 items=100 included=51
2025-08-22 13:32:28,032 INFO app.planning_center.people: [people] page=62 items=100 included=51
2025-08-22 13:32:28,591 INFO app.planning_center.people: [people] page=63 items=100 included=56
2025-08-22 13:32:29,186 INFO app.planning_center.people: [people] page=64 items=100 included=47
2025-08-22 13:32:29,740 INFO app.planning_center.people: [people] page=65 items=100 included=50
2025-08-22 13:33:39,809 INFO app.cadence: [cadence] group upserted=660 people=660 (active now=524)
INFO:     127.0.0.1:61041 - "GET /analytics/cadence/rebuild?signals=attend,give,group,serve&since=2025-08-09&rolling_days=180&week_end=2025-08-17 HTTP/1.1" 200 OK
2025-08-22 13:33:44,307 INFO app.planning_center.people: [people] committed batch upserts hh=227 ppl=500 totals hh=2768 ppl=6500 pages=65 elapsed=1028.8s
2025-08-22 13:33:44,937 INFO app.planning_center.people: [people] page=66 items=100 included=51
2025-08-22 13:33:45,489 INFO app.planning_center.people: [people] page=67 items=100 included=52
2025-08-22 13:33:46,086 INFO app.planning_center.people: [people] page=68 items=100 included=60
2025-08-22 13:33:46,542 INFO app.planning_center.people: [people] page=69 items=100 included=34
2025-08-22 13:33:47,093 INFO app.planning_center.people: [people] page=70 items=100 included=62
2025-08-22 13:35:10,189 INFO app.planning_center.people: [people] committed batch upserts hh=242 ppl=500 totals hh=3010 ppl=7000 pages=70 elapsed=1114.7s
2025-08-22 13:35:10,695 INFO app.planning_center.people: [people] page=71 items=100 included=45
2025-08-22 13:35:11,118 INFO app.planning_center.people: [people] page=72 items=100 included=40
2025-08-22 13:35:11,593 INFO app.planning_center.people: [people] page=73 items=100 included=40
2025-08-22 13:35:12,144 INFO app.planning_center.people: [people] page=74 items=100 included=38
2025-08-22 13:35:12,669 INFO app.planning_center.people: [people] page=75 items=100 included=47
2025-08-22 13:36:09,019 INFO app.cadence: [cadence] attend upserted=1042 people=1042 (window=180d, IO excluded)
2025-08-22 13:36:27,693 INFO app.planning_center.people: [people] committed batch upserts hh=203 ppl=500 totals hh=3213 ppl=7500 pages=75 elapsed=1192.2s
2025-08-22 13:36:28,182 INFO app.planning_center.people: [people] page=76 items=100 included=45
2025-08-22 13:36:28,802 INFO app.planning_center.people: [people] page=77 items=100 included=47
2025-08-22 13:36:29,291 INFO app.planning_center.people: [people] page=78 items=100 included=56
2025-08-22 13:36:29,730 INFO app.planning_center.people: [people] page=79 items=100 included=41
2025-08-22 13:36:30,184 INFO app.planning_center.people: [people] page=80 items=100 included=14
2025-08-22 13:37:44,605 INFO app.planning_center.people: [people] committed batch upserts hh=194 ppl=500 totals hh=3407 ppl=8000 pages=80 elapsed=1269.1s
2025-08-22 13:37:45,042 INFO app.planning_center.people: [people] page=81 items=100 included=19
2025-08-22 13:37:45,524 INFO app.planning_center.people: [people] page=82 items=100 included=21
2025-08-22 13:37:45,949 INFO app.planning_center.people: [people] page=83 items=100 included=34
2025-08-22 13:37:46,609 INFO app.planning_center.people: [people] page=84 items=100 included=40
2025-08-22 13:37:47,108 INFO app.planning_center.people: [people] page=85 items=100 included=52
2025-08-22 13:38:58,530 INFO app.planning_center.people: [people] committed batch upserts hh=156 ppl=500 totals hh=3563 ppl=8500 pages=85 elapsed=1343.0s
2025-08-22 13:38:59,072 INFO app.planning_center.people: [people] page=86 items=100 included=44
2025-08-22 13:38:59,645 INFO app.planning_center.people: [people] page=87 items=100 included=59
2025-08-22 13:39:00,126 INFO app.planning_center.people: [people] page=88 items=100 included=51
2025-08-22 13:39:00,617 INFO app.planning_center.people: [people] page=89 items=100 included=22
2025-08-22 13:39:01,071 INFO app.cadence: [cadence] snap_person_week upserted=1574 for week_end=2025-08-17 (people=1574)
2025-08-22 13:39:01,079 INFO app.planning_center.people: [people] page=90 items=100 included=23
2025-08-22 13:40:14,671 INFO app.planning_center.people: [people] committed batch upserts hh=185 ppl=500 totals hh=3748 ppl=9000 pages=90 elapsed=1419.2s
2025-08-22 13:40:15,222 INFO app.planning_center.people: [people] page=91 items=100 included=39
2025-08-22 13:40:15,784 INFO app.planning_center.people: [people] page=92 items=100 included=50
2025-08-22 13:40:16,402 INFO app.planning_center.people: [people] page=93 items=100 included=59
2025-08-22 13:40:17,024 INFO app.planning_center.people: [people] page=94 items=100 included=87
2025-08-22 13:40:17,597 INFO app.planning_center.people: [people] page=95 items=100 included=88
2025-08-22 13:41:12,180 INFO app.cadence: [cadence] attend upserted=1042 people=1042 (window=180d, IO excluded)
2025-08-22 13:41:39,143 INFO app.planning_center.people: [people] committed batch upserts hh=280 ppl=500 totals hh=4028 ppl=9500 pages=95 elapsed=1503.7s
2025-08-22 13:41:39,749 INFO app.planning_center.people: [people] page=96 items=100 included=86
2025-08-22 13:41:40,337 INFO app.planning_center.people: [people] page=97 items=100 included=87
2025-08-22 13:41:40,895 INFO app.planning_center.people: [people] page=98 items=100 included=84
2025-08-22 13:41:41,582 INFO app.planning_center.people: [people] page=99 items=100 included=81
2025-08-22 13:41:42,290 INFO app.planning_center.people: [people] page=100 items=100 included=53
2025-08-22 13:42:20,624 INFO app.cadence: [cadence] group upserted=660 people=660 (active now=524)
2025-08-22 13:43:05,711 INFO app.planning_center.people: [people] committed batch upserts hh=313 ppl=500 totals hh=4341 ppl=10000 pages=100 elapsed=1590.2s
2025-08-22 13:43:06,341 INFO app.planning_center.people: [people] page=101 items=100 included=44
2025-08-22 13:43:07,113 INFO app.planning_center.people: [people] page=102 items=100 included=46
2025-08-22 13:43:07,869 INFO app.planning_center.people: [people] page=103 items=100 included=43
2025-08-22 13:43:08,522 INFO app.planning_center.people: [people] page=104 items=100 included=44
2025-08-22 13:43:09,264 INFO app.planning_center.people: [people] page=105 items=100 included=51
2025-08-22 13:44:22,250 INFO app.planning_center.people: [people] committed batch upserts hh=213 ppl=500 totals hh=4554 ppl=10500 pages=105 elapsed=1666.8s
2025-08-22 13:44:22,994 INFO app.planning_center.people: [people] page=106 items=100 included=43
2025-08-22 13:44:23,595 INFO app.planning_center.people: [people] page=107 items=100 included=40
2025-08-22 13:44:24,179 INFO app.planning_center.people: [people] page=108 items=100 included=43
2025-08-22 13:44:24,823 INFO app.planning_center.people: [people] page=109 items=100 included=49
2025-08-22 13:44:25,398 INFO app.planning_center.people: [people] page=110 items=100 included=47
2025-08-22 13:45:10,182 INFO app.cadence: [cadence] snap_person_week upserted=1574 for week_end=2025-08-17 (people=1574)
2025-08-22 13:45:39,598 INFO app.planning_center.people: [people] committed batch upserts hh=205 ppl=500 totals hh=4759 ppl=11000 pages=110 elapsed=1744.1s
2025-08-22 13:45:40,278 INFO app.planning_center.people: [people] page=111 items=100 included=34
2025-08-22 13:45:40,898 INFO app.planning_center.people: [people] page=112 items=100 included=33
2025-08-22 13:45:41,506 INFO app.planning_center.people: [people] page=113 items=100 included=31
2025-08-22 13:45:42,042 INFO app.planning_center.people: [people] page=114 items=100 included=33
2025-08-22 13:45:42,661 INFO app.planning_center.people: [people] page=115 items=100 included=34
2025-08-22 13:46:27,024 INFO app.cadence: [cadence] attend upserted=1042 people=1042 (window=180d, IO excluded)
2025-08-22 13:46:51,719 INFO app.planning_center.people: [people] committed batch upserts hh=148 ppl=500 totals hh=4907 ppl=11500 pages=115 elapsed=1816.2s
2025-08-22 13:46:52,373 INFO app.planning_center.people: [people] page=116 items=100 included=35
2025-08-22 13:46:52,952 INFO app.planning_center.people: [people] page=117 items=100 included=35
2025-08-22 13:46:53,648 INFO app.planning_center.people: [people] page=118 items=100 included=45
2025-08-22 13:46:54,279 INFO app.planning_center.people: [people] page=119 items=100 included=34
2025-08-22 13:46:54,914 INFO app.planning_center.people: [people] page=120 items=100 included=44
2025-08-22 13:47:40,766 INFO app.cadence: [cadence] group upserted=660 people=660 (active now=524)
2025-08-22 13:48:09,574 INFO app.planning_center.people: [people] committed batch upserts hh=177 ppl=500 totals hh=5084 ppl=12000 pages=120 elapsed=1894.1s
2025-08-22 13:48:10,240 INFO app.planning_center.people: [people] page=121 items=100 included=37
2025-08-22 13:48:10,872 INFO app.planning_center.people: [people] page=122 items=100 included=46
2025-08-22 13:48:11,528 INFO app.planning_center.people: [people] page=123 items=100 included=42
2025-08-22 13:48:12,107 INFO app.planning_center.people: [people] page=124 items=100 included=39
2025-08-22 13:48:12,759 INFO app.planning_center.people: [people] page=125 items=100 included=34
2025-08-22 13:49:23,272 INFO app.planning_center.people: [people] committed batch upserts hh=181 ppl=500 totals hh=5265 ppl=12500 pages=125 elapsed=1967.8s
2025-08-22 13:49:23,887 INFO app.planning_center.people: [people] page=126 items=100 included=49
2025-08-22 13:49:24,508 INFO app.planning_center.people: [people] page=127 items=100 included=43
2025-08-22 13:49:25,143 INFO app.planning_center.people: [people] page=128 items=100 included=50
2025-08-22 13:49:25,743 INFO app.planning_center.people: [people] page=129 items=100 included=45
2025-08-22 13:49:26,376 INFO app.planning_center.people: [people] page=130 items=100 included=51
2025-08-22 13:50:30,565 INFO app.cadence: [cadence] snap_person_week upserted=1574 for week_end=2025-08-17 (people=1574)
2025-08-22 13:50:45,453 INFO app.planning_center.people: [people] committed batch upserts hh=215 ppl=500 totals hh=5480 ppl=13000 pages=130 elapsed=2050.0s
2025-08-22 13:50:46,358 INFO app.planning_center.people: [people] page=131 items=100 included=48
2025-08-22 13:50:47,021 INFO app.planning_center.people: [people] page=132 items=100 included=49
2025-08-22 13:50:47,670 INFO app.planning_center.people: [people] page=133 items=100 included=41
2025-08-22 13:50:48,510 INFO app.planning_center.people: [people] page=134 items=100 included=44
2025-08-22 13:50:49,273 INFO app.planning_center.people: [people] page=135 items=100 included=50
2025-08-22 13:51:31,594 INFO app.cadence: [cadence] attend upserted=1043 people=1043 (window=180d, IO excluded)
2025-08-22 13:52:10,311 INFO app.planning_center.people: [people] committed batch upserts hh=215 ppl=500 totals hh=5695 ppl=13500 pages=135 elapsed=2134.8s
2025-08-22 13:52:11,089 INFO app.planning_center.people: [people] page=136 items=100 included=40
2025-08-22 13:52:11,511 INFO app.planning_center.people: [people] page=137 items=100 included=4
2025-08-22 13:52:12,110 INFO app.planning_center.people: [people] page=138 items=100 included=39
2025-08-22 13:52:12,746 INFO app.planning_center.people: [people] page=139 items=100 included=39
2025-08-22 13:52:13,487 INFO app.planning_center.people: [people] page=140 items=100 included=48
2025-08-22 13:52:43,293 INFO app.cadence: [cadence] group upserted=660 people=660 (active now=524)
2025-08-22 13:53:26,077 INFO app.planning_center.people: [people] committed batch upserts hh=163 ppl=500 totals hh=5858 ppl=14000 pages=140 elapsed=2210.6s
2025-08-22 13:53:26,712 INFO app.planning_center.people: [people] page=141 items=100 included=35
2025-08-22 13:53:27,423 INFO app.planning_center.people: [people] page=142 items=100 included=41
2025-08-22 13:53:29,030 INFO app.planning_center.people: [people] page=143 items=100 included=49
2025-08-22 13:53:29,710 INFO app.planning_center.people: [people] page=144 items=100 included=41
2025-08-22 13:53:30,337 INFO app.planning_center.people: [people] page=145 items=100 included=45
2025-08-22 13:54:43,871 INFO app.planning_center.people: [people] committed batch upserts hh=195 ppl=500 totals hh=6053 ppl=14500 pages=145 elapsed=2288.4s
2025-08-22 13:54:44,643 INFO app.planning_center.people: [people] page=146 items=100 included=52
2025-08-22 13:54:45,282 INFO app.planning_center.people: [people] page=147 items=100 included=40
2025-08-22 13:54:46,007 INFO app.planning_center.people: [people] page=148 items=100 included=51
2025-08-22 13:54:46,741 INFO app.planning_center.people: [people] page=149 items=100 included=52
2025-08-22 13:54:47,331 INFO app.planning_center.people: [people] page=150 items=100 included=47
2025-08-22 13:55:30,086 INFO app.cadence: [cadence] snap_person_week upserted=1574 for week_end=2025-08-17 (people=1574)
2025-08-22 13:56:08,948 INFO app.planning_center.people: [people] committed batch upserts hh=223 ppl=500 totals hh=6276 ppl=15000 pages=150 elapsed=2373.5s
2025-08-22 13:56:09,615 INFO app.planning_center.people: [people] page=151 items=100 included=56
2025-08-22 13:56:10,355 INFO app.planning_center.people: [people] page=152 items=100 included=59
2025-08-22 13:56:11,139 INFO app.planning_center.people: [people] page=153 items=100 included=47
2025-08-22 13:56:11,831 INFO app.planning_center.people: [people] page=154 items=100 included=41
2025-08-22 13:56:12,531 INFO app.planning_center.people: [people] page=155 items=100 included=40
2025-08-22 13:57:00,987 INFO app.cadence: [cadence] attend upserted=1043 people=1043 (window=180d, IO excluded)
2025-08-22 13:57:34,544 INFO app.planning_center.people: [people] committed batch upserts hh=231 ppl=500 totals hh=6507 ppl=15500 pages=155 elapsed=2459.1s
2025-08-22 13:57:35,229 INFO app.planning_center.people: [people] page=156 items=100 included=42
2025-08-22 13:57:35,732 INFO app.planning_center.people: [people] page=157 items=100 included=18
2025-08-22 13:57:36,342 INFO app.planning_center.people: [people] page=158 items=100 included=28
2025-08-22 13:57:36,998 INFO app.planning_center.people: [people] page=159 items=100 included=44
2025-08-22 13:57:37,632 INFO app.planning_center.people: [people] page=160 items=100 included=36
2025-08-22 13:58:16,826 INFO app.cadence: [cadence] group upserted=660 people=660 (active now=524)
2025-08-22 13:58:48,039 INFO app.planning_center.people: [people] committed batch upserts hh=156 ppl=500 totals hh=6663 ppl=16000 pages=160 elapsed=2532.6s
2025-08-22 13:58:48,729 INFO app.planning_center.people: [people] page=161 items=100 included=38
2025-08-22 13:58:49,378 INFO app.planning_center.people: [people] page=162 items=100 included=43
2025-08-22 13:58:50,032 INFO app.planning_center.people: [people] page=163 items=100 included=41
2025-08-22 13:58:50,676 INFO app.planning_center.people: [people] page=164 items=100 included=27
2025-08-22 13:58:51,343 INFO app.planning_center.people: [people] page=165 items=100 included=41
2025-08-22 14:00:02,000 INFO app.planning_center.people: [people] committed batch upserts hh=185 ppl=500 totals hh=6848 ppl=16500 pages=165 elapsed=2606.5s
2025-08-22 14:00:02,774 INFO app.planning_center.people: [people] page=166 items=100 included=40
2025-08-22 14:00:03,497 INFO app.planning_center.people: [people] page=167 items=100 included=41
2025-08-22 14:00:04,164 INFO app.planning_center.people: [people] page=168 items=100 included=40
2025-08-22 14:00:04,862 INFO app.planning_center.people: [people] page=169 items=100 included=34
2025-08-22 14:00:05,266 INFO app.planning_center.people: [people] page=170 items=59 included=7
2025-08-22 14:01:05,417 INFO app.cadence: [cadence] snap_person_week upserted=1574 for week_end=2025-08-17 (people=1574)
2025-08-22 14:01:12,260 INFO app.planning_center.people: [people] committed batch upserts hh=157 ppl=459 totals hh=7005 ppl=16959 pages=170 elapsed=2676.8s
2025-08-22 14:01:12,261 INFO app.planning_center.people: [people] sync complete pages=170 households=7005 people=16959 elapsed=2676.8s
2025-08-22 14:01:52,582 INFO app.cadence: [cadence] attend upserted=1043 people=1043 (window=180d, IO excluded)
2025-08-22 14:03:02,563 INFO app.cadence: [cadence] group upserted=660 people=660 (active now=524)
2025-08-22 14:06:09,390 INFO app.cadence: [cadence] snap_person_week upserted=1574 for week_end=2025-08-17 (people=1574)
2025-08-22 14:07:07,565 INFO app.cadence: [cadence] attend upserted=1043 people=1043 (window=180d, IO excluded)
2025-08-22 14:08:19,735 INFO app.cadence: [cadence] group upserted=660 people=660 (active now=524)
2025-08-22 14:11:53,775 INFO app.cadence: [cadence] snap_person_week upserted=1574 for week_end=2025-08-17 (people=1574)
2025-08-22 14:12:52,717 INFO app.cadence: [cadence] attend upserted=1043 people=1043 (window=180d, IO excluded)
2025-08-22 14:14:04,922 INFO app.cadence: [cadence] group upserted=660 people=660 (active now=524)
2025-08-22 14:17:04,633 INFO app.cadence: [cadence] snap_person_week upserted=1574 for week_end=2025-08-17 (people=1574)
2025-08-22 14:17:20,865 INFO app.cadence: [cadence] attend upserted=1043 people=1043 (window=180d, IO excluded)
2025-08-22 14:18:32,624 INFO app.cadence: [cadence] group upserted=660 people=660 (active now=524)
2025-08-22 14:20:03,911 INFO googleapiclient.discovery_cache: file_cache is only supported with oauth2client<4.0.0
INFO:     127.0.0.1:61536 - "GET /attendance/process-sheet HTTP/1.1" 200 OK
2025-08-22 14:21:20,876 INFO app.cadence: [cadence] snap_person_week upserted=1574 for week_end=2025-08-17 (people=1574)
2025-08-22 14:21:26,619 INFO app.planning_center.checkins: [checkins] f_checkins_person attempted=678 affected=678 for 2025-08-17
INFO:     127.0.0.1:61540 - "GET /planning-center/checkins HTTP/1.1" 200 OK
2025-08-22 14:21:40,184 INFO app.planning_center.giving: [giving] f_giving_person_week upserted=108 for week_end=2025-08-17 (donors=108)
INFO:     127.0.0.1:61571 - "GET /planning-center/giving/weekly-summary HTTP/1.1" 200 OK
INFO:     127.0.0.1:61583 - "GET /planning-center/groups HTTP/1.1" 200 OK
2025-08-22 14:22:03,766 INFO app.planning_center.serving: [serving] summary source file: /Users/joshuamontoya/np-analytics-app/app/planning_center/serving.py
INFO:     127.0.0.1:61674 - "GET /planning-center/serving/summary HTTP/1.1" 200 OK
2025-08-22 14:22:06,901 INFO googleapiclient.discovery_cache: file_cache is only supported with oauth2client<4.0.0
INFO:     127.0.0.1:61677 - "GET /youtube/weekly-summary HTTP/1.1" 200 OK
2025-08-22 14:22:10,397 INFO googleapiclient.discovery_cache: file_cache is only supported with oauth2client<4.0.0
INFO:     127.0.0.1:61681 - "GET /youtube/livestreams HTTP/1.1" 200 OK
INFO:     127.0.0.1:61686 - "GET /mailchimp/weekly-summary HTTP/1.1" 200 OK